### YamlMime:PythonClass
uid: azure.ai.ml.exceptions.MultipleValueError
name: MultipleValueError
fullName: azure.ai.ml.exceptions.MultipleValueError
module: azure.ai.ml.exceptions
inheritances:
- azure.ai.ml.exceptions.KeywordError
summary: Exception raised when giving multiple value of a keyword parameter in dynamic
  functions.
constructor:
  syntax: MultipleValueError(func_name, keyword)
  parameters:
  - name: func_name
  - name: keyword
methods:
- uid: azure.ai.ml.exceptions.MultipleValueError.add_note
  name: add_note
  summary: "Exception.add_note(note) \u2013\nadd a note to the exception"
  signature: add_note()
- uid: azure.ai.ml.exceptions.MultipleValueError.raise_with_traceback
  name: raise_with_traceback
  summary: 'Raise the exception with the existing traceback.


    Deprecated since version 1.22.0: This method is deprecated as we don''t support
    Python 2 anymore. Use raise/from instead.'
  signature: raise_with_traceback()
- uid: azure.ai.ml.exceptions.MultipleValueError.with_traceback
  name: with_traceback
  summary: "Exception.with_traceback(tb) \u2013\nset self.__traceback__ to tb and\
    \ return self."
  signature: with_traceback()
attributes:
- uid: azure.ai.ml.exceptions.MultipleValueError.args
  name: args
- uid: azure.ai.ml.exceptions.MultipleValueError.error_category
  name: error_category
  summary: Return the error category.
  return:
    description: The error category.
    types:
    - <xref:azure.ai.ml.exceptions.ErrorCategory>
- uid: azure.ai.ml.exceptions.MultipleValueError.no_personal_data_message
  name: no_personal_data_message
  summary: Return the error message with no personal data.
  return:
    description: No personal data error message.
    types:
    - <xref:str>
- uid: azure.ai.ml.exceptions.MultipleValueError.target
  name: target
  summary: Return the error target.
  return:
    description: The error target.
    types:
    - <xref:azure.ai.ml.exceptions.ErrorTarget>
